<?xml version="1.0" encoding="UTF-8"?>
<sdf version='1.9'>
  <model name='spiri_base'>
    <pose>0 0 0 0 0 0</pose>
    <self_collide>false</self_collide>
    <static>false</static>


    <link name="base_link">
		<pose>0 0 0 0 0 0</pose>
		<inertial>
			<pose>0 0.00268 -0.000742 0 0 0</pose>
			<mass>1.437</mass>
			<inertia>
				<ixx>0.1152</ixx>
				<ixy>0</ixy>
				<ixz>0</ixz>
				<iyy>0.1152</iyy>
				<iyz>0</iyz>
				<izz>0.218</izz>
			</inertia>
		</inertial>

      	<gravity>true</gravity>

		<visual name='base_visual'>
			<pose>0 0 0 0 0 3.14</pose>
			<geometry>
				<mesh>
					<scale>1 1 1</scale>
					<uri>model://spiri/meshes/spiri_base_bottom.dae</uri>
				</mesh>
			</geometry>
		</visual>
		<visual name='base_top_visual_1'>
			<pose>0 0 0 0 -0 3.14</pose>
			<geometry>
				<mesh>
					<scale>1 1 1</scale>
					<uri>model://spiri/meshes/spiri_base_top.dae</uri>
				</mesh>
			</geometry>
		</visual>
		<visual name='base_fixed_joint_lump__shank_LF_visual_2'>
			<pose>0.042 0.042 -0.001 0 -0 0.785398</pose>
			<geometry>
				<mesh>
					<scale>1 1 1</scale>
					<uri>model://spiri/meshes/spiri_shank.dae</uri>  
				</mesh>
			</geometry>
		</visual>
		<visual name='base_fixed_joint_lump__shank_LH_visual_3'>
			<pose>-0.042 0.042 -0.001 0 -0 2.35619</pose>
			<geometry>
			<mesh>
				<scale>1 1 1</scale>
				<uri>model://spiri/meshes/spiri_shank.dae</uri>
			</mesh>
			</geometry>
	    </visual>
     	<visual name='base_fixed_joint_lump__shank_RF_visual_4'>
			<pose>0.042 -0.042 -0.001 0 0 -0.785398</pose>
			<geometry>
				<mesh>
					<scale>1 1 1</scale>
					<uri>model://spiri/meshes/spiri_shank.dae</uri>
				</mesh>
			</geometry>
	    </visual>
		<visual name='base_fixed_joint_lump__shank_RH_visual_5'>
			<pose>-0.042 -0.042 -0.001 0 0 -2.35619</pose>
			<geometry>
				<mesh>
					<scale>1 1 1</scale>
					<uri>model://spiri/meshes/spiri_shank.dae</uri>
				</mesh>
			</geometry>
	    </visual>

     	<collision name='base_collision'>
			<pose>0 0 -0.02103 0 -0 0</pose>
			<geometry>
				<box>
					<size>0.21355 0.132 0.04206</size>
				</box>
			</geometry>       
		</collision>
      	<collision name='base_top_collision_1'>
			<pose>0 0 0.03025 0 -0 0</pose>
			<geometry>
				<box>
					<size>0.21355 0.132 0.0605</size>
				</box>
			</geometry>
		</collision>
      	<collision name='base_fixed_joint_lump__shank_LF_collision_2'>
			<pose>0.112711 0.112711 -0.001 0 -0 0.785398</pose>
			<geometry>
				<box>
					<size>0.2 0.014 0.11</size>
				</box>
			</geometry>
		</collision>
      	<collision name='base_fixed_joint_lump__shank_LH_collision_3'>
			<pose>-0.112711 0.112711 -0.001 0 -0 2.35619</pose>
			<geometry>
				<box>
					<size>0.2 0.014 0.11</size>
				</box>
			</geometry>
	    </collision>
      	<collision name='base_fixed_joint_lump__shank_RF_collision_4'>
			<pose>0.112711 -0.112711 -0.001 0 0 -0.785398</pose>
			<geometry>
				<box>
					<size>0.2 0.014 0.11</size>
				</box>
			</geometry>
		</collision>
      	<collision name='base_fixed_joint_lump__shank_RH_collision_5'>
			<pose>-0.112711 -0.112711 -0.001 0 0 -2.35619</pose>
			<geometry>
				<box>
					<size>0.2 0.014 0.11</size>
				</box>
			</geometry>
	    </collision>



      <!-- SENSORS PART -->

      	<sensor name="air_pressure_sensor" type="air_pressure">
			<always_on>1</always_on>
			<update_rate>50</update_rate>
			<air_pressure>
			<pressure>
				<noise type="gaussian">
				<mean>0</mean>
				<stddev>0.01</stddev>
				</noise>
			</pressure>
			</air_pressure>
      	</sensor>

		<sensor name="imu_sensor" type="imu">
			<always_on>1</always_on>
			<update_rate>100</update_rate>
		</sensor>

		<!-- <sensor name="aaaa" type="navsat">
        	<pose>0 0 0 0 0 0</pose>
			<always_on>1</always_on>
			<update_rate>1</update_rate>
        	<topic>navsat</topic>
      	</sensor> -->

    </link>

    <link name='rotor_0'>
  	    <pose>0.165037 -0.165037 0.042 0 0 -0.785398</pose>
        <gravity>true</gravity>
        <self_collide>false</self_collide>
		<inertial>
			<!-- <pose frame=''>0 0 0 0 -0 0</pose> -->
			<mass>0.01</mass>
			<inertia>
				<ixx>0.0005299083</ixx>
				<!-- <ixy>0</ixy> -->
				<!-- <ixz>0</ixz> -->
				<iyy>0.0005235333</iyy>
				<!-- <iyz>0</iyz> -->
				<izz>0.000011775</izz>
			</inertia>
		</inertial>
		<collision name='rotor_0_collision'>
			<pose>0 0 0.009 0 -0 0</pose>
			<geometry>
				<box>
					<size>0.033 0.25 0.018</size>
				</box>
			</geometry>
		</collision>
		<visual name='rotor_0_visual'>
			<pose>0 0 0 0 -0 0.785398</pose>
			<geometry>
				<mesh>
					<scale>1 1 1</scale>
					<uri>model://spiri/meshes/spiri_propeller.dae</uri>   
				</mesh>
			</geometry>
		</visual>
	</link>

    <joint name='rotor_0_joint' type='revolute'>
		<child>rotor_0</child>
		<parent>base_link</parent>
		<axis>
		<xyz>0 0 1</xyz>
		<limit>
			<lower>-1e+16</lower>
			<upper>1e+16</upper>
		</limit>
		<dynamics>
			<spring_reference>0</spring_reference>
			<spring_stiffness>0</spring_stiffness>
		</dynamics>
		<!-- <use_parent_model_frame>1</use_parent_model_frame> -->
		</axis>
	</joint>

    <link name='rotor_1'>
		<!-- <pose frame=''>-0.165037 0.165037 0.042 0 -0 2.35619</pose> -->
        <pose>-0.165037 0.165037 0.042 0 -0 2.35619</pose>
        <gravity>true</gravity>
        <self_collide>false</self_collide>
        <!-- <velocity_decay/> -->
		<inertial>
			<!-- <pose frame=''>0 0 0 0 -0 0</pose> -->
			<mass>0.01</mass>
			<inertia>
				<ixx>0.0005299083</ixx>
				<!-- <ixy>0</ixy> -->
				<!-- <ixz>0</ixz> -->
				<iyy>0.0005235333</iyy>
				<!-- <iyz>0</iyz> -->
				<izz>0.000011775</izz>
			</inertia>
		</inertial>
		<collision name='rotor_1_collision'>
			<pose>0 0 0.009 0 -0 0</pose>
			<geometry>
				<box>
					<size>0.033 0.25 0.018</size>
				</box>
			</geometry>
		</collision>
		<visual name='rotor_1_visual'>
			<pose>0 0 0 0 -0 0.785398</pose>
			<geometry>
				<mesh>
					<scale>1 1 1</scale>
					<uri>model://spiri/meshes/spiri_propeller.dae</uri>
				</mesh>
			</geometry>
		</visual>

	</link>

    <joint name='rotor_1_joint' type='revolute'>
		<child>rotor_1</child>
		<parent>base_link</parent>
		<axis>
			<xyz>0 0 1</xyz>
			<limit>
				<lower>-1e+16</lower>
				<upper>1e+16</upper>
			</limit>
			<dynamics>
				<spring_reference>0</spring_reference>
				<spring_stiffness>0</spring_stiffness>
			</dynamics>
			<!-- <use_parent_model_frame>1</use_parent_model_frame> -->
		</axis>
	  </joint>

    <link name='rotor_2'>
		<!-- <pose frame=''>0.165037 0.165037 0.042 0 -0 0.785398</pose> -->
        <pose>0.165037 0.165037 0.042 0 -0 0.785398</pose>
        <gravity>true</gravity>
        <self_collide>false</self_collide>
        <!-- <velocity_decay/>  -->
		<inertial>
			<!-- <pose frame=''>0 0 0 0 -0 0</pose> -->
			<mass>0.01</mass>
			<inertia>
				<ixx>0.0005299083</ixx>
				<!-- <ixy>0</ixy> -->
				<!-- <ixz>0</ixz> -->
				<iyy>0.0005235333</iyy>
				<!-- <iyz>0</iyz> -->
				<izz>0.000011775</izz>
			</inertia>
		</inertial>
		<collision name='rotor_2_collision'>
			<pose>0 0 0.009 0 -0 0</pose>
			<geometry>
				<box>
					<size>0.033 0.25 0.018</size>
				</box>
			</geometry>
		</collision>
		<visual name='rotor_2_visual'>
			<pose>0 0 0 0 -0 0.785398</pose>
			<geometry>
				<mesh>
					<scale>1 1 1</scale>
					<uri>model://spiri/meshes/spiri_propeller.dae</uri> 
				</mesh>
			</geometry>
		</visual>
	</link>

    <joint name='rotor_2_joint' type='revolute'>
		<child>rotor_2</child>
		<parent>base_link</parent>
		<axis>
			<xyz>0 0 1</xyz>
			<limit>
				<lower>-1e+16</lower>
				<upper>1e+16</upper>
			</limit>
			<dynamics>
				<spring_reference>0</spring_reference>
				<spring_stiffness>0</spring_stiffness>
			</dynamics>
			<!-- <use_parent_model_frame>1</use_parent_model_frame>  -->
		</axis>
	</joint>

    <link name='rotor_3'>
		<!-- <pose frame=''>-0.165037 -0.165037 0.042 0 0 -2.35619</pose> -->
		<pose>-0.165037 -0.165037 0.042 0 0 -2.35619</pose>
		<gravity>true</gravity>
		<self_collide>false</self_collide>
		<!-- <velocity_decay/> -->
		<inertial>
			<!-- <pose frame=''>0 0 0 0 -0 0</pose> -->
			<mass>0.01</mass>
			<inertia>
				<ixx>0.0005299083</ixx>
				<!-- <ixy>0</ixy> -->
				<!-- <ixz>0</ixz> -->
				<iyy>0.0005235333</iyy>
				<!-- <iyz>0</iyz> -->
				<izz>0.000011775</izz>
			</inertia>
		</inertial>
		<collision name='rotor_3_collision'>
			<pose>0 0 0.009 0 -0 0</pose>
			<geometry>
				<box>
					<size>0.033 0.25 0.018</size>
				</box>
			</geometry>
		</collision>
		<visual name='rotor_3_visual'>
			<pose>0 0 0 0 -0 0.785398</pose>
			<geometry>
				<mesh>
					<scale>1 1 1</scale>
					<uri>model://spiri/meshes/spiri_propeller.dae</uri>	            
				</mesh>
			</geometry>
		</visual>
	  </link>

    <joint name='rotor_3_joint' type='revolute'>
		<child>rotor_3</child>
		<parent>base_link</parent>
		<axis>
		<xyz>0 0 1</xyz>
		<limit>
			<lower>-1e+16</lower>
			<upper>1e+16</upper>
		</limit>
		<dynamics>
			<spring_reference>0</spring_reference>
			<spring_stiffness>0</spring_stiffness>
		</dynamics>
		<!-- <use_parent_model_frame>1</use_parent_model_frame> -->
		</axis>
	</joint>
    
  </model>
</sdf>
