<?xml version="1.0" encoding="UTF-8"?>
<sdf version='1.9'>
  <model name="landing_platform">
    <static>false</static>
    <link name="base_link">
      <pose>2 0 0.1 0 0 0</pose>
      <collision name="collision">
        <geometry>
          <box>
            <size>1.5 1.5 0.1</size>
          </box>
        </geometry>
      </collision>
      <visual name="visual">
        <geometry>
          <box>
            <size>1.5 1.5 0.1</size>
          </box>
        </geometry>
        <material>
          <ambient>0.7 0.7 0.7 1</ambient>
          <diffuse>0.7 0.7 0.7 1</diffuse>
        </material>
      </visual>
      <inertial>
        <mass>10</mass>
        <inertia>
          <ixx>1.0</ixx>
          <iyy>1.0</iyy>
          <izz>1.0</izz>
          <ixy>0.0</ixy>
          <ixz>0.0</ixz>
          <iyz>0.0</iyz>
        </inertia>
      </inertial>

      <collision name='caster_collision'>
        <pose>-0.5 0 -0.05 0 0 0</pose>
        <geometry>
            <sphere>
            <radius>.05</radius>
          </sphere>
        </geometry>
        <surface>
          <friction>
            <ode>
              <mu>0</mu>
              <mu2>0</mu2>
              <slip1>1.0</slip1>
              <slip2>1.0</slip2>
            </ode>
          </friction>
        </surface>
      </collision>
      <visual name='caster_visual'>
        <pose>-0.5 0 -0.05 0 0 0</pose>
        <geometry>
          <sphere>
            <radius>.05</radius>
          </sphere>
        </geometry>
      </visual>
    </link>

    <link name="left_wheel">
        <pose>2.5 0.78 0.1 0 1.5707 1.5707</pose>
        <collision name="collision">
          <geometry>
            <cylinder>
              <radius>.1</radius>
              <length>.05</length>
            </cylinder>
          </geometry>
        </collision>
        <visual name="visual">
          <geometry>
            <cylinder>
              <radius>.1</radius>
              <length>.05</length>
            </cylinder>
          </geometry>
        </visual>
      </link>
      <link name="right_wheel">
        <pose>2.5 -0.78 0.1 0 1.5707 1.5707</pose>
        <collision name="collision">
          <geometry>
            <cylinder>
              <radius>.1</radius>
              <length>.05</length>
            </cylinder>
          </geometry>
        </collision>
        <visual name="visual">
          <geometry>
            <cylinder>
              <radius>.1</radius>
              <length>.05</length>
            </cylinder>
          </geometry>
        </visual>
      </link>

    <joint type="revolute" name="left_wheel_joint">
        <pose>2.5 0.78 0.1 0 0 0</pose>
        <child>left_wheel</child>
        <parent>base_link</parent>
        <axis>
          <xyz>0 1 0</xyz>
        </axis>
      </joint>

      <joint type="revolute" name="right_wheel_joint">
        <pose>2.5 -0.78 0.1 0 0 0</pose>
        <child>right_wheel</child>
        <parent>base_link</parent>
        <axis>
          <xyz>0 1 0</xyz>
        </axis>
      </joint>

    <plugin filename="gz-sim-diff-drive-system" name="gz::sim::systems::DiffDrive">
      <right_joint>right_wheel_joint</right_joint>
      <left_joint>left_wheel_joint</left_joint>
      <wheel_separation>1.56</wheel_separation>
      <wheel_radius>0.1</wheel_radius>
      <max_linear_acceleration>10</max_linear_acceleration>
      <odom_publish_frequency>100</odom_publish_frequency>

      <ros>
        <namespace>/landing_platform</namespace>
        <remapping>cmd_vel:=/landing_platform/cmd_vel</remapping>
        <remapping>odom:=/landing_platform/odom</remapping>
      </ros>
    </plugin>

    <plugin filename="gz-sim-joint-state-publisher-system" name="gz::sim::systems::JointStatePublisher">
        <topic>joint_states</topic>
        <joint_name>right_wheel_joint</joint_name>
        <joint_name>left_wheel_joint</joint_name>
    </plugin>
    
  </model>
</sdf>